
# Witch Hut (2 Apr 2014; MC 1.5.*)
# Updated to MC 1.7.10, 10 Oct 2014
# authoring Player: Jordan_Greywolf (based on Vanilla Witch Hut)
# Last Updated: 30 Apr 2015

biomesToSpawnIn=bog,dead swamp,fen,fire swamp,green swampland,lush swamp,marsh,ominous woods,quagmire,sludgepit,swamp,swampland,swampland m,wetlands,bayou,fen

weight=1
embed_into_distance=10


unacceptable_target_blocks=lava,flowing_lava,cloud,Natura:Cloud

dimensions=16,10,7
allowable_overhang=0
max_cut_in=0
cut_in_buffer=0
max_leveling=5
leveling_buffer=0
preserve_water=0
preserve_lava=0
preserve_plants=1

# Terrain Blending
rule01=0,100,PreserveBlock

# Log/Wood (Oak - U/D)
rule02=0,100,minecraft:log-0

# Spruce Plank
rule03=0,100,minecraft:planks-1

# Fence
rule04=0,100,minecraft:fence

# Crafting Table (Workbench)
rule05=0,100,minecraft:crafting_table

# Flowerpot (random content)
rule06=1,100,minecraft:flower_pot-7,minecraft:flower_pot-8,minecraft:flower_pot-10

# Cauldron
rule07=0,100,minecraft:cauldron-1

# Spruce Stairs
rule08=0,100,minecraft:spruce_stairs-0
rule09=0,100,minecraft:spruce_stairs-1
rule10=0,100,minecraft:spruce_stairs-2
rule11=0,100,minecraft:spruce_stairs-3

# Ladder
rule12=2,100,minecraft:ladder-4

# Witch Spawner
rule13=0,100,CommandBlock:RUINSTRIGGER /summon Witch ~0 ~0 ~0 {Equipment:[{Count:1,id:269,tag:{display:{Name:Witch Broom},ench:[{id:20,lvl:2},{id:19,lvl:5},{id:33,lvl:1},{id:34,lvl:3}]}},{},{},{},{}],CustomName:Bog Witch,AbsorptionAmount:5,Attributes:[{Name:generic.maxHealth,Base:50}],DropChances:[1.0F,0.0F,0.0F,0.0F,0.0F],PersistenceRequired:1}:@

# Chest
rule14=0,100,EasyChest

#
# Layout
# 

# Supports (-10)
layer
01,01,01,01,01,01,01
01,01,01,01,01,01,01
01,01,01,01,01,01,01
01,02,01,01,01,02,01
01,01,01,01,01,01,01
01,01,01,01,01,01,01
01,01,01,01,01,01,01
01,01,01,01,01,01,01
01,02,01,01,01,02,01
01,01,01,01,01,01,01
endlayer


# Supports (-9)
layer
01,01,01,01,01,01,01
01,01,01,01,01,01,01
01,01,01,01,01,01,01
01,02,01,01,01,02,01
01,01,01,01,01,01,01
01,01,01,01,01,01,01
01,01,01,01,01,01,01
01,01,01,01,01,01,01
01,02,01,01,01,02,01
01,01,01,01,01,01,01
endlayer


# Supports (-8)
layer
01,01,01,01,01,01,01
01,01,01,01,01,01,01
01,01,01,01,01,01,01
01,02,01,01,01,02,01
01,01,01,01,01,01,01
01,01,01,01,01,01,01
01,01,01,01,01,01,01
01,01,01,01,01,01,01
01,02,01,01,01,02,01
01,01,01,01,01,01,01
endlayer


# Supports (-7)
layer
01,01,01,01,01,01,01
01,01,01,01,01,01,01
01,01,01,01,01,01,01
01,02,01,01,01,02,01
01,01,01,01,01,01,01
01,01,01,01,01,01,01
01,01,01,01,01,01,01
01,01,01,01,01,01,01
01,02,01,01,01,02,01
01,01,01,01,01,01,01
endlayer


# Supports (-6)
layer
01,01,01,01,01,01,01
01,01,01,01,01,01,01
01,01,01,01,01,01,01
01,02,01,01,01,02,01
01,01,01,01,01,01,01
01,01,01,01,01,01,01
01,01,01,01,01,01,01
01,01,01,01,01,01,01
01,02,01,01,01,02,01
01,01,01,01,01,01,01
endlayer

# Supports (-5)
layer
01,01,01,01,01,01,01
01,01,01,01,01,01,01
01,01,01,01,01,01,01
01,02,01,01,01,02,01
01,01,01,01,01,01,01
01,01,01,01,01,01,01
01,01,01,01,01,01,01
01,01,01,01,01,01,01
01,02,01,01,01,02,01
01,01,01,01,01,01,01
endlayer


# Supports (-4)
layer
01,01,01,01,01,01,01
01,01,01,01,01,01,01
01,01,01,01,01,01,01
01,02,01,01,01,02,01
01,01,01,01,01,01,01
01,01,01,01,01,01,01
01,01,01,01,01,01,01
01,01,01,01,01,01,01
01,02,01,01,01,02,01
01,01,01,01,01,01,01
endlayer


# Supports (-3)
layer
01,01,01,01,01,01,01
01,01,01,01,01,01,01
01,01,01,01,01,01,01
01,02,01,01,01,02,01
01,01,01,01,01,01,01
01,01,01,01,01,01,01
01,01,01,01,01,01,01
01,01,01,01,01,01,01
01,02,01,01,01,02,01
01,01,01,01,01,01,01
endlayer


# Supports (-2)
layer
01,01,01,01,01,01,01
01,01,01,01,01,01,01
01,01,01,01,01,01,01
01,02,01,01,01,02,01
01,01,01,01,01,01,01
01,01,01,01,01,01,01
01,01,01,01,01,01,01
01,01,01,01,01,01,01
01,02,01,01,01,02,01
01,01,01,01,01,01,01
endlayer


# Supports (-1)
layer
01,01,01,01,01,01,01
01,01,01,01,01,01,01
01,01,01,01,01,01,01
01,02,01,01,01,02,01
01,01,01,01,01,01,01
01,01,01,01,01,01,01
01,01,01,01,01,01,01
01,01,01,01,01,01,01
01,02,01,01,01,02,01
01,01,01,01,01,01,01
endlayer

# Supports (+1)
layer
01,01,01,12,01,01,01
01,01,01,03,01,01,01
01,01,01,01,01,01,01
01,02,01,01,01,02,01
01,01,01,01,01,01,01
01,01,01,01,01,01,01
01,01,01,01,01,01,01
01,01,01,01,01,01,01
01,02,01,01,01,02,01
01,01,01,01,01,01,01
endlayer

# Supports (+2)
layer
01,01,00,12,00,01,01
01,01,00,03,00,01,01
01,00,00,00,00,00,01
00,02,00,00,00,02,00
00,00,00,00,00,00,00
00,00,00,00,00,00,00
00,00,00,00,00,00,00
00,00,00,00,00,00,00
01,02,00,00,00,02,01
01,01,00,00,00,01,01
endlayer

# Floor (+3)
layer
01,00,00,12,00,00,01
00,00,03,03,03,00,00
00,03,03,03,03,03,00
00,02,03,03,03,02,00
00,03,03,03,03,03,00
00,03,03,03,03,03,00
00,03,03,03,03,03,00
00,03,03,03,03,03,00
00,02,03,03,03,02,00
01,00,00,00,00,00,01
endlayer

# Lower Interior (+4)
layer
00,00,00,00,00,00,00
00,00,00,00,00,00,00
00,04,00,00,00,04,00
00,02,03,03,00,02,00
00,03,00,00,00,03,00
00,03,00,13,00,03,00
00,03,00,00,00,03,00
00,03,07,05,14,03,00
00,02,03,03,03,02,00
00,00,00,00,00,00,00
endlayer

# Upper Interior (+5)
layer
00,00,00,00,00,00,00
00,00,00,00,00,00,00
00,00,00,00,00,00,00
00,02,00,03,00,02,00
00,03,00,00,00,03,00
00,00,00,00,00,00,00
00,00,00,00,00,06,00
00,03,00,00,00,03,00
00,02,03,04,03,02,00
00,00,00,00,00,00,00
endlayer

# Roof (+6)
layer
00,00,00,00,00,00,00
00,00,00,00,00,00,00
08,08,08,08,08,08,08
11,03,03,03,03,03,10
11,03,03,03,03,03,10
11,03,03,03,03,03,10
11,03,03,03,03,03,10
11,03,03,03,03,03,10
11,03,03,03,03,03,10
09,09,09,09,09,09,09
endlayer



